<?xml version='1.0' encoding='utf-8'?>
<mujoco><mjmodel time="0" timestep="0.01" gravity="0 0 -9.81" invmartrix_solimp="0.9 0.95 0.001" rabbit_viscous="0" solver_error_tolerance="0.0001" solver_residue_tolerance="0.0001" solver_velocity_tolerance="1e-12"><option integrator="RK4" timestep="0.001" /><size nxmax="500" nymax="500" nconmax="100" /><body name="torso" pos="0 0 1.2"><geom type="capsule" fromto="0 0 0 0 0 -0.3" size="0.3" /><body name="head" pos="0 0 0.3"><geom type="sphere" size="0.2" /></body><body name="leftarm" pos="-0.3 0 0"><joint name="leftshoulder" type="hinge" limited="true" damping="1.0" /><geom type="capsule" fromto="0 0 0 0 -0.3 0" size="0.1" /><body name="lefthand" pos="0 -0.3 0"><geom type="sphere" size="0.15" /></body></body><body name="rightarm" pos="0.3 0 0"><joint name="rightshoulder" type="hinge" limited="true" damping="1.0" /><geom type="capsule" fromto="0 0 0 0 -0.3 0" size="0.1" /><body name="righthand" pos="0 -0.3 0"><geom type="sphere" size="0.15" /></body></body><body name="leftleg" pos="-0.15 0 0" euler="0 -0.785 0"><joint name="lefthip" type="hinge" limited="true" damping="1.0" /><geom type="capsule" fromto="0 0 0 0 -0.4 0" size="0.15" /><body name="leftfoot" pos="0 -0.4 -0.1" euler="0 -0.785 0"><geom type="box" size="0.2 0.5 0.1" /></body></body><body name="rightleg" pos="0.15 0 0" euler="0 0.785 0"><joint name="righthip" type="hinge" limited="true" damping="1.0" /><geom type="capsule" fromto="0 0 0 0 -0.4 0" size="0.15" /><body name="rightfoot" pos="0 -0.4 -0.1" euler="0 0.785 0"><geom type="box" size="0.2 0.5 0.1" /></body></body></body></mjmodel></mujoco>