<?xml version='1.0' encoding='utf-8'?>
<mujoco model="biped">
	<compiler angle="degree" coordinate="local" inertiafromgeom="true" />
	<option integrator="RK4" timestep="0.01" />
	<default>
		<joint armature="1" damping="1" limited="true" />
		<geom conaffinity="0" condim="3" density="5.0" friction="1 0.5 0.5" margin="0.01" rgba="0.8 0.6 0.4 1" />
	</default>
	<asset>
		<texture builtin="gradient" height="100" rgb1="1 1 1" rgb2="0 0 0" type="skybox" width="100" />
		<texture builtin="flat" height="1278" mark="cross" markrgb="1 1 1" name="texgeom" random="0.01" rgb1="0.8 0.6 0.4" rgb2="0.8 0.6 0.4" type="cube" />
		<texture builtin="checker" height="100" name="texplane" rgb1="0 0 0" rgb2="0.8 0.8 0.8" type="2d" width="100" />
		<material name="geom" texture="texgeom" texuniform="true" />
		<material name="MatPlane" reflectance="0.5" shininess="1" specular="1" texrepeat="60 60" texture="texplane" />
	</asset>
	<worldbody>
		<light cutoff="100" diffuse="1 1 1" dir="-0 0 -1.3" directional="true" exponent="1" pos="0 0 1.3" specular=".1 .1 .1" />
		<geom conaffinity="1" condim="3" material="MatPlane" name="floor" pos="0 0 0" rgba="0.8 0.9 0.8 1" size="40 40 40" type="plane" />
		<body>
			<geom name="torso_geom" pos=" 0.2   0.2   0.2 " size=" 0.2 " type="sphere" />
			<joint armature=" 10 " damping=" 1.0 " name="root" pos=" 0.2   0.2   0.2 " type="free" />
			<inertial mass=" 10 " pos=" 0.2   0.2   0.2 " />
			<body>
				<geom fromto="0 0 0 0 -0.2 -0.2" name="right_thigh" size=" 0.05 " type="capsule" />
				<joint axis="0 1 1" name="right_hip" pos="0 -0.2 -0.2" range="-30 30" type="hinge" />
				<inertial mass="2" pos="0 -0.2 -0.2" />
				<body>
					<geom fromto="0 0 0 0 -0.2 -0.2" name="rightshin" size="0.05" type="capsule" />
					<joint axis="1 1 0" name="rightknee" pos="0 -0.2 -0.2" range="-150 0" type="hinge" />
					<inertial mass=" 2 " pos="0 -0.2 -0.2" />
					<body>
						<geom fromto="0 0 0 0.1 0 0" name="rightfoot" size="0.04" type="capsule" />
						<joint axis="-1 1 1" name="rightankle" pos="0 -0.2 -0.2" range="-45 45" type="hinge" />
						<inertial mass=" 0.5 " pos="0.05 0 0" />
					</body>
				</body>
			</body>
			<body>
				<geom fromto="0 0 0 0 0.2 -0.2" name="leftthight" size="0.05" type="capsule" />
				<joint axis="0 -1 1" name="lefthip" pos="0 0.2 -0.2" range="-30 30" type="hinge" />
				<inertial mass="2" pos="0 0.2 -0.2" />
				<body>
					<geom fromto="0 0 0 0 0.2 -0.2" name="leftshin" size="0.05" type="capsule" />
					<joint axis="-1 1 0" name="leftknee" pos="0 0.2 -0.2" range="-150 0" type="hinge" />
					<inertial mass=" 2 " pos="0 0.2 -0.2" />
					<body>
						<geom fromto="0 0 0 -0.1 0 0" name="leftfoot" size="0.04" type="capsule" />
						<joint axis="1 1 -1" name="leftankle" pos="0 0.2 -0.2" range="-45 45" type="hinge" />
						<inertial mass=" 0.5 " pos="-0.05 0 0" />
					</body>
				</body>
			</body>
			<body>
				<geom name="head" pos="0 0.2 0.2" size="0.1" type="sphere" />
				<joint axis="1 1 1" name="neck" pos="0 0.2 0.2" range="-90 90" type="hinge" />
				<inertial mass=" 1 " pos="0 0.2 0.2" />
			</body>
			<body>
				<geom fromto="0 0 0 -0.15 0 0" name="rightarm" size="0.04" type="capsule" />
				<joint axis="-1 -1 -1" name="rightshoulder" pos="0 0.2 0.2" range="-180 180" type="hinge" />
				<inertial mass=" 1 " pos="0.075 0 0" />
			</body>
			<body>
				<geom fromto="0 0 0 0.15 0 0" name="leftarm" size="0.04" type="capsule" />
				<joint axis="1 -1 -1" name="leftshoulder" pos="0 0.2 0.2" range="-180 180" type="hinge" />
				<inertial mass=" 1 " />
			</body>
		</body>
	</worldbody>
</mujoco>