<mujoco model="humanoid">
	<worldbody>
		<geom type="plane" size="100 100 0.1"/>
		<body name="humanoid" pos="0 0 1.4">
			<joint name="head_joint" type="free" axis="z" pos="0 0 1.6"/>
			<geom name="head_geom" type="sphere" size="0.15"/>
			<joint name="torso_joint" type="free" axis="z" pos="0 0 0"/>
			<geom name="torso_geom" type="sphere" size="0.15 0.2"/>
			<joint name="right_arm_joint" type="hinge" axis="-x" pos="-0.2 0 1.6"/>
			<geom name="right_arm_geom" type="capsule" size="0.2 0.04"/>
			<joint name="left_arm_joint" type="hinge" axis="-x" pos="0.2 0 1.6"/>
			<geom name="left_arm_geom" type="capsule" size="0.2 0.04"/>
			<joint name="right_leg_joint" type="hinge" axis="-y,-x,-z,-y,-x,-z" pos="0 0 0"/>
			<geom name="right_leg_geom" type="capsule" size="-1 -1 1 -1 -1 -1"/>
			<joint name="left_leg_joint" type="hinge" axis="-y,x,z,-y,x,z" pos="0 0 0"/>
			<geom name="left_leg_geom" type="capsule" size="-1 -1 -1 -1 -1 -1"/>
		</body>
	</worldbody>
</mujoco>
